<?xml version="1.0" ?>
<!-- Generated using onshape-to-robot -->
<!-- Onshape https://cad.onshape.com/documents/0a0f899ce59c60b61859c991/w/d22d541f278fbcb2dfd45b88/e/3d0f6edf0206f9f0b58d8fd9 -->
<mujoco model="bananaHand">
  <compiler angle="radian" meshdir="assets" autolimits="true"/>
  <default>
    <default class="bananaHand">
      <joint damping="0.0005"/>
      <position kp="2000" dampratio="0.0001"/>
      <default class="visual">
        <geom type="mesh" contype="0" conaffinity="0" group="2"/>
      </default>
      <default class="collision">
        <geom group="3"/>
      </default>
    </default>
  </default>
  <worldbody>
    <!-- Link wrist_mount -->
    <body name="wrist_mount" pos="0 0 0" quat="1 0 0 0" childclass="bananaHand">
      <inertial pos="-6.18886e-06 -0.00237089 0.0161077" mass="0.103992" fullinertia="5.21252e-05 5.33286e-05 5.15278e-05 -3.087e-09 2.8937e-08 6.35601e-06"/>
      <!-- Part wrist_mount -->
      <geom type="mesh" class="visual" pos="-0.00291653 -0 0.0813183" quat="1 -0 -0 -0" mesh="wrist_mount" material="wrist_mount_material"/>
      <!-- Link hand_base -->
      <body name="hand_base" pos="-0.01886 -0.003 0.05977" quat="0.707107 0.707107 -0 0">
        <!-- Joint from wrist_mount to hand_base -->
        <!-- Joint is "fixed", skipping it -->
        <inertial pos="0.0227711 0.0368198 -0.00970441" mass="0.24691" fullinertia="0.00031481 0.000210808 0.000492602 4.41066e-06 -8.72699e-06 6.42656e-06"/>
        <!-- Part hand_base -->
        <geom type="mesh" class="visual" pos="0.0159435 0.0215483 -0.003" quat="0.707107 -0.707107 0 -0" mesh="hand_base" material="hand_base_material"/>
        <!-- Frame closing_thumbpivot_1 -->
        <site group="3" name="closing_thumbpivot_1" pos="0.058502 0.0313007 0.0215" quat="0.704416 0.704416 0.0616284 0.0616284"/>
        <!-- Frame closing_thumbpivot_1_z -->
        <site group="3" name="closing_thumbpivot_1_z" pos="0.0758669 -0.0671801 0.0215" quat="0.704416 0.704416 0.0616284 0.0616284"/>
        <!-- Link index_base -->
        <body name="index_base" pos="0.0607318 0.108855 -0.008" quat="0 -1 0 -0">
          <!-- Joint from hand_base to index_base -->
          <!-- Joint is "fixed", skipping it -->
          <inertial pos="-0.000915189 0.0173428 0.00659471" mass="0.00908632" fullinertia="3.91326e-06 7.16004e-07 3.97477e-06 9.919e-08 2.4255e-08 -8.53174e-07"/>
          <!-- Part index_base -->
          <geom type="mesh" class="visual" pos="-0.0447883 0.0873066 -0.005" quat="0.707107 0.707107 -0 -0" mesh="index_base" material="index_base_material"/>
          <!-- Frame closing_indexrev3_2 -->
          <site group="3" name="closing_indexrev3_2" pos="-0.00379499 -0.0116902 0.003" quat="0.0293023 -0.706499 -0.0293023 -0.706499"/>
          <!-- Frame closing_indexrev3_2_z -->
          <site group="3" name="closing_indexrev3_2_z" pos="0.0958616 -0.00340937 0.003" quat="0.0293023 -0.706499 -0.0293023 -0.706499"/>
          <!-- Link actuator_housing -->
          <body name="actuator_housing" pos="-0.000613381 0.0375721 0.0185" quat="0.706541 -0.030325 0.706456 0.0282795">
            <!-- Joint from index_base to actuator_housing -->
            <joint axis="0 0 1" name="indexrev1" type="hinge"/>
            <inertial pos="-0.00615503 -0.0206966 -0.0025" mass="0.012849" fullinertia="1.75829e-06 7.16933e-07 1.97489e-06 -4.3769e-08 -0 -0"/>
            <!-- Part actuator_housing -->
            <geom type="mesh" class="visual" pos="0 -0.003 -0.0025" quat="0.707107 0.707107 -0 0" mesh="actuator_housing" material="actuator_housing_material"/>
            <!-- Link actuator_piston -->
            <body name="actuator_piston" pos="-0 -0.00975 -0.0025" quat="0 -0 0.707107 0.707107">
              <!-- Joint from actuator_housing to actuator_piston -->
              <joint axis="0 0 1" name="indexpiston" type="slide" range="-0.01825000000000018 -1.7802599672211983e-16"/>
              <inertial pos="-0 -0 -0.0184461" mass="0.00107731" fullinertia="1.20116e-07 1.20153e-07 4.363e-09 0 0 0"/>
              <!-- Part actuator_piston -->
              <geom type="mesh" class="visual" pos="-0 -0 0" quat="0 1 0 0" mesh="actuator_piston" material="actuator_piston_material"/>
              <!-- Link mcp_1 -->
              <body name="mcp_1" pos="-0 -0.00314 -0.0341" quat="0.696301 -0.696301 0.123148 0.123148">
                <!-- Joint from actuator_piston to mcp_1 -->
                <joint axis="0 0 1" name="indexrev2" type="hinge"/>
                <inertial pos="-0.00396774 0.02456 0.00314" mass="0.00589055" fullinertia="1.69298e-06 3.16979e-07 1.6373e-06 1.9048e-07 -0 -0"/>
                <!-- Part mcp_1 -->
                <geom type="mesh" class="visual" pos="-0.013 0.01 0.00314" quat="0.707107 -0.707107 -0 -0" mesh="mcp_1" material="mcp_1_material"/>
                <!-- Frame closing_indexrev3_1 -->
                <site group="3" name="closing_indexrev3_1" pos="-0.013 0.01 -0.00161" quat="1 0 0 0"/>
                <!-- Frame closing_indexrev3_1_z -->
                <site group="3" name="closing_indexrev3_1_z" pos="-0.013 0.01 0.09839" quat="1 0 0 0"/>
                <!-- Frame closing_indexrev7_2 -->
                <site group="3" name="closing_indexrev7_2" pos="0 0.05 0.00774" quat="1 0 0 0"/>
                <!-- Frame closing_indexrev7_2_z -->
                <site group="3" name="closing_indexrev7_2_z" pos="0 0.05 0.10774" quat="1 0 0 0"/>
                <!-- Link pip_2 -->
                <body name="pip_2" pos="-0.0106252 0.047153 0.00464" quat="0.973728 0 0 -0.227713">
                  <!-- Joint from mcp_1 to pip_2 -->
                  <joint axis="0 0 1" name="indexrev5" type="hinge"/>
                  <inertial pos="-3.24138e-05 0.0189849 -0.0015" mass="0.00113266" fullinertia="1.54822e-07 7.08e-09 1.60354e-07 -3.423e-09 0 -0"/>
                  <!-- Part pip_2 -->
                  <geom type="mesh" class="visual" pos="0 0.015 -0.0015" quat="0.707107 -0.707107 -0 0" mesh="pip_2" material="pip_2_material"/>
                  <!-- Link dip_1 -->
                  <body name="dip_1" pos="-0 0.0365 0.0001" quat="0 0.918852 0.394602 -0">
                    <!-- Joint from pip_2 to dip_1 -->
                    <joint axis="0 0 1" name="indexrev8" type="hinge" range="-1.2831247046461076 0.08370581700023294"/>
                    <inertial pos="-0.00485498 -0.0148401 0.0016" mass="0.00216187" fullinertia="1.7401e-07 5.3677e-08 1.93366e-07 -5.2995e-08 0 -0"/>
                    <!-- Part dip_1 -->
                    <geom type="mesh" class="visual" pos="-0.0075 -0.01 0.0016" quat="0.707107 0.707107 0 0" mesh="dip_1" material="dip_1_material"/>
                    <!-- Frame closing_indexrev9_1 -->
                    <site group="3" name="closing_indexrev9_1" pos="-0.0075 -0.01 0.0001" quat="0 1 0 0"/>
                    <!-- Frame closing_indexrev9_1_z -->
                    <site group="3" name="closing_indexrev9_1_z" pos="-0.0075 -0.01 -0.0999" quat="0 1 0 0"/>
                    <!-- Link fingertip -->
                    <body name="fingertip" pos="-0.00325 -0.025 0.0016" quat="0.707107 0 -0.707107 -0">
                      <!-- Joint from dip_1 to fingertip -->
                      <!-- Joint is "fixed", skipping it -->
                      <inertial pos="-1.53313e-05 -5.21544e-05 0.00584875" mass="0.00193004" fullinertia="1.24126e-07 1.07425e-07 1.27251e-07 -1.77e-10 4.9e-11 -9.13e-09"/>
                      <!-- Part fingertip -->
                      <geom type="mesh" class="visual" pos="0 0.015 0.00425" quat="0.5 0.5 0.5 -0.5" mesh="fingertip" material="fingertip_material"/>
                    </body>
                  </body>
                </body>
              </body>
            </body>
          </body>
          <!-- Link mcp_2 -->
          <body name="mcp_2" pos="-0.000183516 -0.0159056 -0.006" quat="0.677803 -0.144632 -0.692157 0.201452">
            <!-- Joint from index_base to mcp_2 -->
            <joint axis="0 0 1" name="indexrev4" type="hinge"/>
            <inertial pos="-0.000980814 -0.0151619 -0.0015" mass="0.00128032" fullinertia="1.51146e-07 1.3562e-08 1.62937e-07 -1.728e-08 0 -0"/>
            <!-- Part mcp_2 -->
            <geom type="mesh" class="visual" pos="-0 0 -0.0015" quat="0.5 0.5 0.5 -0.5" mesh="mcp_2" material="mcp_2_material"/>
            <!-- Link pip_1 -->
            <body name="pip_1" pos="-0.005 -0.0325 -0.0031" quat="0.883363 0 0 -0.46869">
              <!-- Joint from mcp_2 to pip_1 -->
              <joint axis="0 0 1" name="indexrev6" type="hinge" range="-0.98788114855292 0.10779664540511469"/>
              <inertial pos="0.000173285 -0.0227423 0.0016" mass="0.00231455" fullinertia="4.46291e-07 3.2362e-08 4.34547e-07 -2.143e-09 -0 0"/>
              <!-- Part pip_1 -->
              <geom type="mesh" class="visual" pos="-0 -0.0074 0.0016" quat="0.707107 0.707107 0 0" mesh="pip_1" material="pip_1_material"/>
              <!-- Frame closing_indexrev7_1 -->
              <site group="3" name="closing_indexrev7_1" pos="0 -0.0074 -0.003" quat="0 1 0 0"/>
              <!-- Frame closing_indexrev7_1_z -->
              <site group="3" name="closing_indexrev7_1_z" pos="0 -0.0074 -0.103" quat="0 1 0 0"/>
              <!-- Frame closing_indexrev9_2 -->
              <site group="3" name="closing_indexrev9_2" pos="0 -0.0444 0.0001" quat="0 1 0 0"/>
              <!-- Frame closing_indexrev9_2_z -->
              <site group="3" name="closing_indexrev9_2_z" pos="0 -0.0444 -0.0999" quat="0 1 0 0"/>
            </body>
          </body>
        </body>
        <!-- Link middle_base -->
        <body name="middle_base" pos="0.0343032 0.108855 -0.008" quat="0 -1 0 -0">
          <!-- Joint from hand_base to middle_base -->
          <!-- Joint is "fixed", skipping it -->
          <inertial pos="-0.00110743 0.0165611 0.00645915" mass="0.00951968" fullinertia="4.19962e-06 7.54185e-07 4.25616e-06 -1.1399e-08 1.5511e-08 -9.14817e-07"/>
          <!-- Part middle_base -->
          <geom type="mesh" class="visual" pos="-0.0183597 0.0873066 -0.005" quat="0.707107 0.707107 -0 0" mesh="middle_base" material="middle_base_material"/>
          <!-- Frame closing_middlerev3_2 -->
          <site group="3" name="closing_middlerev3_2" pos="0.00496225 -0.0121185 0.003" quat="0.70708 0.00617059 -0.70708 0.00617059"/>
          <!-- Frame closing_middlerev3_2_z -->
          <site group="3" name="closing_middlerev3_2_z" pos="-0.0950225 -0.0138638 0.003" quat="0.70708 0.00617059 -0.70708 0.00617059"/>
          <!-- Link actuator_housing_2 -->
          <body name="actuator_housing_2" pos="0.0018604 0.0366644 0.0185" quat="0.707088 -0.00724924 0.70707 0.00509193">
            <!-- Joint from middle_base to actuator_housing_2 -->
            <joint axis="0 0 1" name="middlerev1" type="hinge"/>
            <inertial pos="-0.00615503 -0.0206966 -0.0025" mass="0.012849" fullinertia="1.75829e-06 7.16933e-07 1.97489e-06 -4.3769e-08 -0 0"/>
            <!-- Part actuator_housing_2 -->
            <geom type="mesh" class="visual" pos="0 -0.003 -0.0025" quat="0.707107 0.707107 -0 -0" mesh="actuator_housing" material="actuator_housing_material"/>
            <!-- Link actuator_piston_2 -->
            <body name="actuator_piston_2" pos="-0 -0.0097717 -0.0025" quat="0 0 -0.707107 -0.707107">
              <!-- Joint from actuator_housing_2 to actuator_piston_2 -->
              <joint axis="0 0 1" name="middlepiston" type="slide" range="-0.018228303046465586 2.169695353441514e-05"/>
              <inertial pos="0 -0 -0.0184461" mass="0.00107731" fullinertia="1.20116e-07 1.20153e-07 4.363e-09 0 0 -0"/>
              <!-- Part actuator_piston_2 -->
              <geom type="mesh" class="visual" pos="0 0 -0" quat="0 1 0 0" mesh="actuator_piston" material="actuator_piston_material"/>
              <!-- Link mcp_1_2 -->
              <body name="mcp_1_2" pos="0 0.0036 -0.0341" quat="0.696206 0.696206 0.123685 -0.123685">
                <!-- Joint from actuator_piston_2 to mcp_1_2 -->
                <joint axis="0 0 1" name="middlerev2" type="hinge"/>
                <inertial pos="-0.00396774 -0.02456 0.0036" mass="0.00589055" fullinertia="1.69298e-06 3.16979e-07 1.6373e-06 -1.9048e-07 0 -0"/>
                <!-- Part mcp_1_2 -->
                <geom type="mesh" class="visual" pos="-0.013 -0.01 0.0036" quat="0.707107 0.707107 -0 -0" mesh="mcp_1" material="mcp_1_material"/>
                <!-- Frame closing_middlerev3_1 -->
                <site group="3" name="closing_middlerev3_1" pos="-0.013 -0.01 -0.00115" quat="1 -0 0 0"/>
                <!-- Frame closing_middlerev3_1_z -->
                <site group="3" name="closing_middlerev3_1_z" pos="-0.013 -0.01 0.09885" quat="1 -0 0 0"/>
                <!-- Frame closing_middlerev7_2 -->
                <site group="3" name="closing_middlerev7_2" pos="0 -0.05 -0.001" quat="0 1 0 0"/>
                <!-- Frame closing_middlerev7_2_z -->
                <site group="3" name="closing_middlerev7_2_z" pos="0 -0.05 -0.101" quat="0 1 0 0"/>
                <!-- Link pip_2_2 -->
                <body name="pip_2_2" pos="-0.0106252 -0.047153 0.0021" quat="0 -0.973953 -0.226751 0">
                  <!-- Joint from mcp_1_2 to pip_2_2 -->
                  <joint axis="0 0 1" name="middlerev5" type="hinge"/>
                  <inertial pos="-3.24138e-05 0.0189849 -0.0015" mass="0.00113266" fullinertia="1.54822e-07 7.08e-09 1.60354e-07 -3.423e-09 0 0"/>
                  <!-- Part pip_2_2 -->
                  <geom type="mesh" class="visual" pos="0 0.015 -0.0015" quat="0.707107 -0.707107 -0 0" mesh="pip_2" material="pip_2_material"/>
                  <!-- Link dip_1_2 -->
                  <body name="dip_1_2" pos="0 0.0365 0.0001" quat="0 -0.918403 -0.395646 -0">
                    <!-- Joint from pip_2_2 to dip_1_2 -->
                    <joint axis="0 0 1" name="middlerev8" type="hinge" range="-1.2808536958560035 0.08597682579033705"/>
                    <inertial pos="-0.00485498 -0.0148401 0.0016" mass="0.00216187" fullinertia="1.7401e-07 5.3677e-08 1.93366e-07 -5.2995e-08 0 -0"/>
                    <!-- Part dip_1_2 -->
                    <geom type="mesh" class="visual" pos="-0.0075 -0.01 0.0016" quat="0.707107 0.707107 0 0" mesh="dip_1" material="dip_1_material"/>
                    <!-- Frame closing_middlerev9_1 -->
                    <site group="3" name="closing_middlerev9_1" pos="-0.0075 -0.01 0.0001" quat="0 1 0 0"/>
                    <!-- Frame closing_middlerev9_1_z -->
                    <site group="3" name="closing_middlerev9_1_z" pos="-0.0075 -0.01 -0.0999" quat="0 1 0 0"/>
                    <!-- Link fingertip_2 -->
                    <body name="fingertip_2" pos="-0.00325 -0.025 0.0016" quat="0.707107 -0 -0.707107 -0">
                      <!-- Joint from dip_1_2 to fingertip_2 -->
                      <!-- Joint is "fixed", skipping it -->
                      <inertial pos="-1.53313e-05 -5.21544e-05 0.00584875" mass="0.00193004" fullinertia="1.24126e-07 1.07425e-07 1.27251e-07 -1.77e-10 4.9e-11 -9.13e-09"/>
                      <!-- Part fingertip_2 -->
                      <geom type="mesh" class="visual" pos="0 0.015 0.00425" quat="0.5 0.5 0.5 -0.5" mesh="fingertip" material="fingertip_material"/>
                    </body>
                  </body>
                </body>
              </body>
            </body>
          </body>
          <!-- Link mcp_2_2 -->
          <body name="mcp_2_2" pos="0.00179128 -0.0166746 -0.006" quat="0.166841 0.684125 0.178808 0.687142">
            <!-- Joint from middle_base to mcp_2_2 -->
            <joint axis="0 0 1" name="middlerev4" type="hinge"/>
            <inertial pos="-0.000980814 0.0151619 -0.0015" mass="0.00128032" fullinertia="1.51146e-07 1.3562e-08 1.62937e-07 1.728e-08 0 0"/>
            <!-- Part mcp_2_2 -->
            <geom type="mesh" class="visual" pos="-0 0 -0.0015" quat="0.5 -0.5 -0.5 -0.5" mesh="mcp_2" material="mcp_2_material"/>
            <!-- Link pip_1_2 -->
            <body name="pip_1_2" pos="-0.005 0.0325 0.0001" quat="0 -0.882685 -0.469965 -0">
              <!-- Joint from mcp_2_2 to pip_1_2 -->
              <joint axis="0 0 1" name="middlerev6" type="hinge" range="-0.984993611771781 0.11068418218625364"/>
              <inertial pos="0.000173285 -0.0227423 0.0016" mass="0.00231455" fullinertia="4.46291e-07 3.2362e-08 4.34547e-07 -2.143e-09 0 -0"/>
              <!-- Part pip_1_2 -->
              <geom type="mesh" class="visual" pos="0 -0.0074 0.0016" quat="0.707107 0.707107 -0 -0" mesh="pip_1" material="pip_1_material"/>
              <!-- Frame closing_middlerev7_1 -->
              <site group="3" name="closing_middlerev7_1" pos="0 -0.0074 -0.003" quat="0 1 0 0"/>
              <!-- Frame closing_middlerev7_1_z -->
              <site group="3" name="closing_middlerev7_1_z" pos="0 -0.0074 -0.103" quat="0 1 0 0"/>
              <!-- Frame closing_middlerev9_2 -->
              <site group="3" name="closing_middlerev9_2" pos="-0 -0.0444 0.0001" quat="0 1 0 0"/>
              <!-- Frame closing_middlerev9_2_z -->
              <site group="3" name="closing_middlerev9_2_z" pos="0 -0.0444 -0.0999" quat="0 1 0 0"/>
            </body>
          </body>
        </body>
        <!-- Link ring_base -->
        <body name="ring_base" pos="0.00840738 0.108855 -0.008" quat="0 -1 0 -0">
          <!-- Joint from hand_base to ring_base -->
          <!-- Joint is "fixed", skipping it -->
          <inertial pos="0.000885706 0.0164993 0.00649729" mass="0.00986702" fullinertia="4.24391e-06 7.83956e-07 4.32174e-06 1.1066e-08 -1.1259e-08 -9.22392e-07"/>
          <!-- Part ring_base -->
          <geom type="mesh" class="visual" pos="0.00753608 0.0873066 -0.005" quat="0.707107 0.707107 -0 0" mesh="ring_base" material="ring_base_material"/>
          <!-- Frame closing_ringrev3_2 -->
          <site group="3" name="closing_ringrev3_2" pos="0.00464272 -0.0123136 0.003" quat="0.7071 -0.00308533 -0.7071 -0.00308533"/>
          <!-- Frame closing_ringrev3_2_z -->
          <site group="3" name="closing_ringrev3_2_z" pos="-0.0953535 -0.011441 0.003" quat="0.7071 -0.00308533 -0.7071 -0.00308533"/>
          <!-- Link actuator_housing_3 -->
          <body name="actuator_housing_3" pos="0.00281892 0.0365337 0.0185" quat="0.707104 0.00416413 0.707095 -0.00200651">
            <!-- Joint from ring_base to actuator_housing_3 -->
            <joint axis="0 0 1" name="ringrev1" type="hinge"/>
            <inertial pos="-0.00615503 -0.0206966 -0.0025" mass="0.012849" fullinertia="1.75829e-06 7.16933e-07 1.97489e-06 -4.3769e-08 -0 0"/>
            <!-- Part actuator_housing_3 -->
            <geom type="mesh" class="visual" pos="0 -0.003 -0.0025" quat="0.707107 0.707107 -0 0" mesh="actuator_housing" material="actuator_housing_material"/>
            <!-- Link actuator_piston_3 -->
            <body name="actuator_piston_3" pos="-0 -0.0090018 -0.0025" quat="0 -0 0.707107 0.707107">
              <!-- Joint from actuator_housing_3 to actuator_piston_3 -->
              <joint axis="0 0 1" name="ringpiston" type="slide" range="-0.018998200437010764 1.7995629892377223e-06"/>
              <inertial pos="0 -0 -0.0184461" mass="0.00107731" fullinertia="1.20116e-07 1.20153e-07 4.363e-09 0 0 0"/>
              <!-- Part actuator_piston_3 -->
              <geom type="mesh" class="visual" pos="0 0 0" quat="0 1 0 0" mesh="actuator_piston" material="actuator_piston_material"/>
              <!-- Link mcp_1_3 -->
              <body name="mcp_1_3" pos="0 0.0036 -0.0341" quat="0.699383 0.699383 0.104229 -0.104229">
                <!-- Joint from actuator_piston_3 to mcp_1_3 -->
                <joint axis="0 0 1" name="ringrev2" type="hinge"/>
                <inertial pos="-0.00396774 -0.02456 0.0036" mass="0.00589055" fullinertia="1.69298e-06 3.16979e-07 1.6373e-06 -1.9048e-07 0 -0"/>
                <!-- Part mcp_1_3 -->
                <geom type="mesh" class="visual" pos="-0.013 -0.01 0.0036" quat="0.707107 0.707107 -0 -0" mesh="mcp_1" material="mcp_1_material"/>
                <!-- Frame closing_ringrev3_1 -->
                <site group="3" name="closing_ringrev3_1" pos="-0.013 -0.01 -0.00115" quat="1 -0 -0 -0"/>
                <!-- Frame closing_ringrev3_1_z -->
                <site group="3" name="closing_ringrev3_1_z" pos="-0.013 -0.01 0.09885" quat="1 -0 -0 -0"/>
                <!-- Frame closing_ringrev7_2 -->
                <site group="3" name="closing_ringrev7_2" pos="0 -0.05 -0.001" quat="0 1 0 0"/>
                <!-- Frame closing_ringrev7_2_z -->
                <site group="3" name="closing_ringrev7_2_z" pos="0 -0.05 -0.101" quat="0 1 0 0"/>
                <!-- Link pip_2_3 -->
                <body name="pip_2_3" pos="-0.0106252 -0.047153 0.0021" quat="0 0.965008 0.26222 0">
                  <!-- Joint from mcp_1_3 to pip_2_3 -->
                  <joint axis="0 0 1" name="ringrev5" type="hinge"/>
                  <inertial pos="-3.24138e-05 0.0189849 -0.0015" mass="0.00113266" fullinertia="1.54822e-07 7.08e-09 1.60354e-07 -3.423e-09 -0 0"/>
                  <!-- Part pip_2_3 -->
                  <geom type="mesh" class="visual" pos="0 0.015 -0.0015" quat="0.707107 -0.707107 -0 0" mesh="pip_2" material="pip_2_material"/>
                  <!-- Link dip_1_3 -->
                  <body name="dip_1_3" pos="0 0.0365 0.0001" quat="0 -0.93452 -0.355911 -0">
                    <!-- Joint from pip_2_3 to dip_1_3 -->
                    <joint axis="0 0 1" name="ringrev8" type="hinge" range="-1.366617383255992 0.00021313839034853288"/>
                    <inertial pos="-0.00485498 -0.0148401 0.0016" mass="0.00216187" fullinertia="1.7401e-07 5.3677e-08 1.93366e-07 -5.2995e-08 0 -0"/>
                    <!-- Part dip_1_3 -->
                    <geom type="mesh" class="visual" pos="-0.0075 -0.01 0.0016" quat="0.707107 0.707107 0 0" mesh="dip_1" material="dip_1_material"/>
                    <!-- Frame closing_ringrev9_1 -->
                    <site group="3" name="closing_ringrev9_1" pos="-0.0075 -0.01 0.0001" quat="0 1 0 0"/>
                    <!-- Frame closing_ringrev9_1_z -->
                    <site group="3" name="closing_ringrev9_1_z" pos="-0.0075 -0.01 -0.0999" quat="0 1 0 0"/>
                    <!-- Link fingertip_3 -->
                    <body name="fingertip_3" pos="-0.00325 -0.025 0.0016" quat="0.707107 -0 -0.707107 -0">
                      <!-- Joint from dip_1_3 to fingertip_3 -->
                      <!-- Joint is "fixed", skipping it -->
                      <inertial pos="-1.53313e-05 -5.21544e-05 0.00584875" mass="0.00193004" fullinertia="1.24126e-07 1.07425e-07 1.27251e-07 -1.77e-10 4.9e-11 -9.13e-09"/>
                      <!-- Part fingertip_3 -->
                      <geom type="mesh" class="visual" pos="0 0.015 0.00425" quat="0.5 0.5 0.5 -0.5" mesh="fingertip" material="fingertip_material"/>
                    </body>
                  </body>
                </body>
              </body>
            </body>
          </body>
          <!-- Link mcp_2_3 -->
          <body name="mcp_2_3" pos="0.00135358 -0.0167851 -0.006" quat="0.188011 0.683268 0.182056 0.681654">
            <!-- Joint from ring_base to mcp_2_3 -->
            <joint axis="0 0 1" name="ringrev4" type="hinge"/>
            <inertial pos="-0.000980814 0.0151619 -0.0015" mass="0.00128032" fullinertia="1.51146e-07 1.3562e-08 1.62937e-07 1.728e-08 0 0"/>
            <!-- Part mcp_2_3 -->
            <geom type="mesh" class="visual" pos="-0 0 -0.0015" quat="0.5 -0.5 -0.5 -0.5" mesh="mcp_2" material="mcp_2_material"/>
            <!-- Link pip_1_3 -->
            <body name="pip_1_3" pos="-0.005 0.0325 0.0001" quat="0 0.90727 0.420548 -0">
              <!-- Joint from mcp_2_3 to pip_1_3 -->
              <joint axis="0 0 1" name="ringrev6" type="hinge" range="-1.0953978737612031 0.0002799201968315401"/>
              <inertial pos="0.000173285 -0.0227423 0.0016" mass="0.00231455" fullinertia="4.46291e-07 3.2362e-08 4.34547e-07 -2.143e-09 0 0"/>
              <!-- Part pip_1_3 -->
              <geom type="mesh" class="visual" pos="0 -0.0074 0.0016" quat="0.707107 0.707107 -0 0" mesh="pip_1" material="pip_1_material"/>
              <!-- Frame closing_ringrev7_1 -->
              <site group="3" name="closing_ringrev7_1" pos="0 -0.0074 -0.003" quat="0 1 0 0"/>
              <!-- Frame closing_ringrev7_1_z -->
              <site group="3" name="closing_ringrev7_1_z" pos="0 -0.0074 -0.103" quat="0 1 0 0"/>
              <!-- Frame closing_ringrev9_2 -->
              <site group="3" name="closing_ringrev9_2" pos="0 -0.0444 0.0001" quat="0 1 0 0"/>
              <!-- Frame closing_ringrev9_2_z -->
              <site group="3" name="closing_ringrev9_2_z" pos="0 -0.0444 -0.0999" quat="0 1 0 0"/>
            </body>
          </body>
        </body>
        <!-- Link pinky_base -->
        <body name="pinky_base" pos="-0.0181011 0.108855 -0.008" quat="0 -1 0 -0">
          <!-- Joint from hand_base to pinky_base -->
          <!-- Joint is "fixed", skipping it -->
          <inertial pos="0.00108912 0.0171044 0.00656354" mass="0.0094602" fullinertia="4.07813e-06 7.5829e-07 4.15727e-06 -1.11179e-07 -2.491e-08 -8.89574e-07"/>
          <!-- Part pinky_base -->
          <geom type="mesh" class="visual" pos="0.0340445 0.0873066 -0.005" quat="0.707107 0.707107 -0 0" mesh="pinky_base" material="pinky_base_material"/>
          <!-- Frame closing_pinkyrev3_2 -->
          <site group="3" name="closing_pinkyrev3_2" pos="0.00412758 -0.0120009 0.003" quat="0.706864 -0.0185099 -0.706864 -0.0185099"/>
          <!-- Frame closing_pinkyrev3_2_z -->
          <site group="3" name="closing_pinkyrev3_2_z" pos="-0.0957354 -0.00676726 0.003" quat="0.706864 -0.0185099 -0.706864 -0.0185099"/>
          <!-- Link actuator_housing_4 -->
          <body name="actuator_housing_4" pos="0.00444357 0.0370201 0.0185" quat="0.706892 0.0195903 0.706835 -0.0174294">
            <!-- Joint from pinky_base to actuator_housing_4 -->
            <joint axis="0 0 1" name="pinkyrev1" type="hinge"/>
            <inertial pos="-0.00615503 -0.0206966 -0.0025" mass="0.012849" fullinertia="1.75829e-06 7.16933e-07 1.97489e-06 -4.3769e-08 -0 0"/>
            <!-- Part actuator_housing_4 -->
            <geom type="mesh" class="visual" pos="0 -0.003 -0.0025" quat="0.707107 0.707107 -0 0" mesh="actuator_housing" material="actuator_housing_material"/>
            <!-- Link actuator_piston_4 -->
            <body name="actuator_piston_4" pos="0 -0.00914072 -0.0025" quat="0 -0 0.707107 0.707107">
              <!-- Joint from actuator_housing_4 to actuator_piston_4 -->
              <joint axis="0 0 1" name="pinkypiston" type="slide" range="-0.018859275737118673 0.0001407242628813268"/>
              <inertial pos="0 -0 -0.0184461" mass="0.00107731" fullinertia="1.20116e-07 1.20153e-07 4.363e-09 0 0 0"/>
              <!-- Part actuator_piston_4 -->
              <geom type="mesh" class="visual" pos="0 -0 0" quat="0 1 0 0" mesh="actuator_piston" material="actuator_piston_material"/>
              <!-- Link mcp_1_4 -->
              <body name="mcp_1_4" pos="0 0.0036 -0.0341" quat="0.699389 0.699389 0.104187 -0.104187">
                <!-- Joint from actuator_piston_4 to mcp_1_4 -->
                <joint axis="0 0 1" name="pinkyrev2" type="hinge"/>
                <inertial pos="-0.00396774 -0.02456 0.0036" mass="0.00589055" fullinertia="1.69298e-06 3.16979e-07 1.6373e-06 -1.9048e-07 0 -0"/>
                <!-- Part mcp_1_4 -->
                <geom type="mesh" class="visual" pos="-0.013 -0.01 0.0036" quat="0.707107 0.707107 0 -0" mesh="mcp_1" material="mcp_1_material"/>
                <!-- Frame closing_pinkyrev3_1 -->
                <site group="3" name="closing_pinkyrev3_1" pos="-0.013 -0.01 -0.00115" quat="1 -0 -0 0"/>
                <!-- Frame closing_pinkyrev3_1_z -->
                <site group="3" name="closing_pinkyrev3_1_z" pos="-0.013 -0.01 0.09885" quat="1 -0 -0 0"/>
                <!-- Frame closing_pinkyrev7_2 -->
                <site group="3" name="closing_pinkyrev7_2" pos="0 -0.05 -0.001" quat="0 1 0 0"/>
                <!-- Frame closing_pinkyrev7_2_z -->
                <site group="3" name="closing_pinkyrev7_2_z" pos="0 -0.05 -0.101" quat="0 1 0 0"/>
                <!-- Link pip_2_4 -->
                <body name="pip_2_4" pos="-0.0106252 -0.047153 0.0021" quat="0 -0.964985 -0.262306 0">
                  <!-- Joint from mcp_1_4 to pip_2_4 -->
                  <joint axis="0 0 1" name="pinkyrev5" type="hinge"/>
                  <inertial pos="-3.24138e-05 0.0189849 -0.0015" mass="0.00113266" fullinertia="1.54822e-07 7.08e-09 1.60354e-07 -3.423e-09 0 -0"/>
                  <!-- Part pip_2_4 -->
                  <geom type="mesh" class="visual" pos="0 0.015 -0.0015" quat="0.707107 -0.707107 -0 -0" mesh="pip_2" material="pip_2_material"/>
                  <!-- Link dip_1_4 -->
                  <body name="dip_1_4" pos="0 0.0365 0.0001" quat="0 0.934558 0.355812 -0">
                    <!-- Joint from pip_2_4 to dip_1_4 -->
                    <joint axis="0 0 1" name="pinkyrev8" type="hinge" range="-1.3668305216460332 3.0730973321624333e-13"/>
                    <inertial pos="-0.00485498 -0.0148401 0.0016" mass="0.00216187" fullinertia="1.7401e-07 5.3677e-08 1.93366e-07 -5.2995e-08 0 -0"/>
                    <!-- Part dip_1_4 -->
                    <geom type="mesh" class="visual" pos="-0.0075 -0.01 0.0016" quat="0.707107 0.707107 -0 0" mesh="dip_1" material="dip_1_material"/>
                    <!-- Frame closing_pinkyrev9_1 -->
                    <site group="3" name="closing_pinkyrev9_1" pos="-0.0075 -0.01 0.0001" quat="0 1 0 0"/>
                    <!-- Frame closing_pinkyrev9_1_z -->
                    <site group="3" name="closing_pinkyrev9_1_z" pos="-0.0075 -0.01 -0.0999" quat="0 1 0 0"/>
                    <!-- Link fingertip_4 -->
                    <body name="fingertip_4" pos="-0.00325 -0.025 0.0016" quat="0.707107 -0 -0.707107 -0">
                      <!-- Joint from dip_1_4 to fingertip_4 -->
                      <!-- Joint is "fixed", skipping it -->
                      <inertial pos="-1.53313e-05 -5.21544e-05 0.00584875" mass="0.00193004" fullinertia="1.24126e-07 1.07425e-07 1.27251e-07 -1.77e-10 4.9e-11 -9.13e-09"/>
                      <!-- Part fingertip_4 -->
                      <geom type="mesh" class="visual" pos="0 0.015 0.00425" quat="0.5 0.5 0.5 -0.5" mesh="fingertip" material="fingertip_material"/>
                    </body>
                  </body>
                </body>
              </body>
            </body>
          </body>
          <!-- Link mcp_2_4 -->
          <body name="mcp_2_4" pos="0.000646523 -0.0163246 -0.006" quat="0.202863 0.687071 0.167134 0.677382">
            <!-- Joint from pinky_base to mcp_2_4 -->
            <joint axis="0 0 1" name="pinkyrev4" type="hinge"/>
            <inertial pos="-0.000980814 0.0151619 -0.0015" mass="0.00128032" fullinertia="1.51146e-07 1.3562e-08 1.62937e-07 1.728e-08 0 -0"/>
            <!-- Part mcp_2_4 -->
            <geom type="mesh" class="visual" pos="0 -0 -0.0015" quat="0.5 -0.5 -0.5 -0.5" mesh="mcp_2" material="mcp_2_material"/>
            <!-- Link pip_1_4 -->
            <body name="pip_1_4" pos="-0.005 0.0325 0.0001" quat="0 -0.907329 -0.420422 -0">
              <!-- Joint from mcp_2_4 to pip_1_4 -->
              <joint axis="0 0 1" name="pinkyrev6" type="hinge" range="-1.095675671969139 2.121988895709137e-06"/>
              <inertial pos="0.000173285 -0.0227423 0.0016" mass="0.00231455" fullinertia="4.46291e-07 3.2362e-08 4.34547e-07 -2.143e-09 0 -0"/>
              <!-- Part pip_1_4 -->
              <geom type="mesh" class="visual" pos="0 -0.0074 0.0016" quat="0.707107 0.707107 0 0" mesh="pip_1" material="pip_1_material"/>
              <!-- Frame closing_pinkyrev7_1 -->
              <site group="3" name="closing_pinkyrev7_1" pos="0 -0.0074 -0.003" quat="0 1 0 0"/>
              <!-- Frame closing_pinkyrev7_1_z -->
              <site group="3" name="closing_pinkyrev7_1_z" pos="-0 -0.0074 -0.103" quat="0 1 0 0"/>
              <!-- Frame closing_pinkyrev9_2 -->
              <site group="3" name="closing_pinkyrev9_2" pos="0 -0.0444 0.0001" quat="0 1 0 0"/>
              <!-- Frame closing_pinkyrev9_2_z -->
              <site group="3" name="closing_pinkyrev9_2_z" pos="0 -0.0444 -0.0999" quat="0 1 0 0"/>
            </body>
          </body>
        </body>
        <!-- Link actuator_housing_5 -->
        <body name="actuator_housing_5" pos="-0.00280284 0.0161755 0.004" quat="0 -0.766044 0.642788 0">
          <!-- Joint from hand_base to actuator_housing_5 -->
          <!-- Joint is "fixed", skipping it -->
          <inertial pos="-0.00615503 -0.0206966 -0.0025" mass="0.012849" fullinertia="1.75829e-06 7.16933e-07 1.97489e-06 -4.3769e-08 -0 0"/>
          <!-- Part actuator_housing_5 -->
          <geom type="mesh" class="visual" pos="0 -0.003 -0.0025" quat="0.707107 0.707107 0 -0" mesh="actuator_housing" material="actuator_housing_material"/>
          <!-- Link actuator_piston_5 -->
          <body name="actuator_piston_5" pos="-0 -0.008 -0.0025" quat="0.707107 -0.707107 0 -0">
            <!-- Joint from actuator_housing_5 to actuator_piston_5 -->
            <joint axis="0 0 1" name="tmpiston" type="slide" range="-0.01409470539354365 0.004155294606456351"/>
            <inertial pos="0 0 -0.0243514" mass="0.00107731" fullinertia="1.20116e-07 1.20153e-07 4.363e-09 0 0 0"/>
            <!-- Part actuator_piston_5 -->
            <geom type="mesh" class="visual" pos="0 0 -0.00590529" quat="0 -1 -0 -0" mesh="actuator_piston" material="actuator_piston_material"/>
            <!-- Link clevis_1 -->
            <body name="clevis_1" pos="0 0 -0.0400053" quat="0.707107 -0.707107 -0 0">
              <!-- Joint from actuator_piston_5 to clevis_1 -->
              <!-- Joint is "fixed", skipping it -->
              <inertial pos="5.3e-11 0.00537033 -1.5e-11" mass="0.000506548" fullinertia="1.1958e-08 7.212e-09 9.774e-09 -0 -0 0"/>
              <!-- Part clevis_1 -->
              <geom type="mesh" class="visual" pos="-0 0 0" quat="0.5 0.5 0.5 0.5" mesh="clevis_1" material="clevis_1_material"/>
              <!-- Link clevis_link -->
              <body name="clevis_link" pos="0 0.0095 0" quat="0.580099 -0.404332 -0.580099 0.404332">
                <!-- Joint from clevis_1 to clevis_link -->
                <joint axis="0 0 1" name="clevisrev1" type="hinge"/>
                <inertial pos="0.00375 -0 -0" mass="0.000355327" fullinertia="2.452e-09 5.429e-09 7.348e-09 -0 -0 -0"/>
                <!-- Part clevis_link -->
                <geom type="mesh" class="visual" pos="0 0 0" quat="0 1 0 0" mesh="clevis_link" material="clevis_link_material"/>
                <!-- Link thumb_base -->
                <body name="thumb_base" pos="0.0075 -0 0.00165" quat="0 0.783482 -0.621414 0">
                  <!-- Joint from clevis_link to thumb_base -->
                  <joint axis="0 0 1" name="clevisrev2" type="hinge"/>
                  <inertial pos="0.0251383 -0.0184421 -0.00915858" mass="0.0120829" fullinertia="4.78938e-06 4.16123e-06 3.24283e-06 1.0924e-06 1.19264e-06 -1.65223e-06"/>
                  <!-- Part thumb_base -->
                  <geom type="mesh" class="visual" pos="0 0 0.00165" quat="0 1 0 0" mesh="thumb_base" material="thumb_base_material"/>
                  <!-- Frame closing_thumbpivot_2 -->
                  <site group="3" name="closing_thumbpivot_2" pos="0.0125 0 -0.0026" quat="0.707107 0 0 -0.707107"/>
                  <!-- Frame closing_thumbpivot_2_z -->
                  <site group="3" name="closing_thumbpivot_2_z" pos="0.0125 0 0.0974" quat="0.707107 0 0 -0.707107"/>
                  <!-- Frame closing_thumbrev3_2 -->
                  <site group="3" name="closing_thumbrev3_2" pos="0.0416809 -0.0333933 -0.0305794" quat="0.627211 0.627211 -0.326506 -0.326506"/>
                  <!-- Frame closing_thumbrev3_2_z -->
                  <site group="3" name="closing_thumbrev3_2_z" pos="-0.0402343 -0.090751 -0.0305794" quat="0.627211 0.627211 -0.326506 -0.326506"/>
                  <!-- Link actuator_housing_6 -->
                  <body name="actuator_housing_6" pos="0.0230205 -0.0106663 0.0141002" quat="0.422774 -0.706789 0.0212128 -0.5668">
                    <!-- Joint from thumb_base to actuator_housing_6 -->
                    <joint axis="0 0 1" name="thumbrev1" type="hinge"/>
                    <inertial pos="-0.00615503 0.0206966 -0.0025" mass="0.012849" fullinertia="1.75829e-06 7.16933e-07 1.97489e-06 4.3769e-08 -0 0"/>
                    <!-- Part actuator_housing_6 -->
                    <geom type="mesh" class="visual" pos="0 0.003 -0.0025" quat="0.707107 -0.707107 -0 -0" mesh="actuator_housing" material="actuator_housing_material"/>
                    <!-- Link actuator_piston_6 -->
                    <body name="actuator_piston_6" pos="0 0.008 -0.0025" quat="0.707107 0.707107 0 -0">
                      <!-- Joint from actuator_housing_6 to actuator_piston_6 -->
                      <joint axis="0 0 1" name="thumbpiston" type="slide" range="-0.017994745372570658 0.000505254627429343"/>
                      <inertial pos="0 0 -0.0204513" mass="0.00107731" fullinertia="1.20116e-07 1.20153e-07 4.363e-09 0 0 0"/>
                      <!-- Part actuator_piston_6 -->
                      <geom type="mesh" class="visual" pos="0 0 -0.00200525" quat="0 -1 -0 -0" mesh="actuator_piston" material="actuator_piston_material"/>
                      <!-- Link tm_1 -->
                      <body name="tm_1" pos="0 0.0036 -0.0361053" quat="0.693777 0.693777 0.136649 -0.136649">
                        <!-- Joint from actuator_piston_6 to tm_1 -->
                        <joint axis="0 0 1" name="thumbrev2" type="hinge"/>
                        <inertial pos="-0.00380679 -0.026257 0.0036" mass="0.00431327" fullinertia="1.35778e-06 2.40329e-07 1.29668e-06 -1.57822e-07 0 1e-12"/>
                        <!-- Part tm_1 -->
                        <geom type="mesh" class="visual" pos="-0.013 -0.0125 0.0036" quat="0.707107 0.707107 0 -0" mesh="tm_1" material="tm_1_material"/>
                        <!-- Frame closing_thumbrev3_1 -->
                        <site group="3" name="closing_thumbrev3_1" pos="-0.013 -0.0125 -0.00115" quat="1 0 0 0"/>
                        <!-- Frame closing_thumbrev3_1_z -->
                        <site group="3" name="closing_thumbrev3_1_z" pos="-0.013 -0.0125 0.09885" quat="1 0 0 0"/>
                        <!-- Frame closing_thumbrev7_2 -->
                        <site group="3" name="closing_thumbrev7_2" pos="0 -0.0525 -0.001" quat="0 -1 -0 0"/>
                        <!-- Frame closing_thumbrev7_2_z -->
                        <site group="3" name="closing_thumbrev7_2_z" pos="0 -0.0525 -0.101" quat="0 -1 -0 0"/>
                        <!-- Link pipt_2 -->
                        <body name="pipt_2" pos="-0.0106252 -0.049653 0.0021" quat="0 -0.93656 -0.350506 0">
                          <!-- Joint from tm_1 to pipt_2 -->
                          <joint axis="0 0 1" name="thumbrev5" type="hinge"/>
                          <inertial pos="-0.000173862 0.0153854 -0.0015" mass="0.000915658" fullinertia="9.0128e-08 5.242e-09 9.4123e-08 -1.255e-09 -0 0"/>
                          <!-- Part pipt_2 -->
                          <geom type="mesh" class="visual" pos="0 0.015 -0.0015" quat="0.707107 -0.707107 -0 -0" mesh="pipt_2" material="pipt_2_material"/>
                          <!-- Link dipt_1 -->
                          <body name="dipt_1" pos="0 0.03 0.0001" quat="0 0.918792 0.394742 0">
                            <!-- Joint from pipt_2 to dipt_1 -->
                            <joint axis="0 0 1" name="thumbrev8" type="hinge" range="-1.2828219215344872 0.0840086001118534"/>
                            <inertial pos="-0.00431974 -0.0180421 0.0016" mass="0.00248918" fullinertia="2.59013e-07 6.5044e-08 2.83639e-07 -7.5169e-08 0 -0"/>
                            <!-- Part dipt_1 -->
                            <geom type="mesh" class="visual" pos="-0.0075 -0.015 0.0016" quat="0.707107 0.707107 0 0" mesh="dipt_1" material="dipt_1_material"/>
                            <!-- Frame closing_thumbrev9_1 -->
                            <site group="3" name="closing_thumbrev9_1" pos="-0.0075 -0.015 0.0001" quat="0 1 0 0"/>
                            <!-- Frame closing_thumbrev9_1_z -->
                            <site group="3" name="closing_thumbrev9_1_z" pos="-0.0075 -0.015 -0.0999" quat="0 1 0 0"/>
                            <!-- Link fingertip_5 -->
                            <body name="fingertip_5" pos="-0.00325 -0.03 0.0016" quat="0.707107 -0 -0.707107 -0">
                              <!-- Joint from dipt_1 to fingertip_5 -->
                              <!-- Joint is "fixed", skipping it -->
                              <inertial pos="-1.53313e-05 -5.21544e-05 0.00584875" mass="0.00193004" fullinertia="1.24126e-07 1.07425e-07 1.27251e-07 -1.77e-10 4.9e-11 -9.13e-09"/>
                              <!-- Part fingertip_5 -->
                              <geom type="mesh" class="visual" pos="0 0.015 0.00425" quat="0.5 0.5 0.5 -0.5" mesh="fingertip" material="fingertip_material"/>
                            </body>
                          </body>
                        </body>
                      </body>
                    </body>
                  </body>
                  <!-- Link tm_2 -->
                  <body name="tm_2" pos="0.0376777 -0.0333424 -0.0403664" quat="0.274596 -0.69127 -0.148812 -0.651611">
                    <!-- Joint from thumb_base to tm_2 -->
                    <joint axis="0 0 1" name="thumbrev4" type="hinge"/>
                    <inertial pos="-0.00110758 0.0136603 -0.0015" mass="0.00116349" fullinertia="1.18886e-07 1.2458e-08 1.29727e-07 1.6468e-08 -0 -0"/>
                    <!-- Part tm_2 -->
                    <geom type="mesh" class="visual" pos="0 0 -0.0015" quat="0.5 -0.5 -0.5 -0.5" mesh="tm_2" material="tm_2_material"/>
                    <!-- Link pipt_1 -->
                    <body name="pipt_1" pos="-0.005 0.03 0.0001" quat="0 0.907327 0.420425 -0">
                      <!-- Joint from tm_2 to pipt_1 -->
                      <joint axis="0 0 1" name="thumbrev6" type="hinge" range="-1.9247003724121732 8.816243168396909e-06"/>
                      <inertial pos="0.000183014 -0.0220653 0.0016" mass="0.0021915" fullinertia="3.96143e-07 3.0505e-08 3.85335e-07 -1.029e-09 -0 0"/>
                      <!-- Part pipt_1 -->
                      <geom type="mesh" class="visual" pos="0 -0.0095 0.0016" quat="0.707107 0.707107 -0 0" mesh="pipt_1" material="pipt_1_material"/>
                      <!-- Frame closing_thumbrev7_1 -->
                      <site group="3" name="closing_thumbrev7_1" pos="0 -0.0095 -0.003" quat="0 1 0 0"/>
                      <!-- Frame closing_thumbrev7_1_z -->
                      <site group="3" name="closing_thumbrev7_1_z" pos="0 -0.0095 -0.103" quat="0 1 0 0"/>
                      <!-- Frame closing_thumbrev9_2 -->
                      <site group="3" name="closing_thumbrev9_2" pos="0 -0.0435 0.0001" quat="0 1 0 0"/>
                      <!-- Frame closing_thumbrev9_2_z -->
                      <site group="3" name="closing_thumbrev9_2_z" pos="0 -0.0435 -0.0999" quat="0 1 0 0"/>
                    </body>
                  </body>
                </body>
              </body>
            </body>
          </body>
        </body>
        <!-- Link palm_shell -->
        <body name="palm_shell" pos="0.0359559 0.01125 0.0156" quat="0 -1 0 -0">
          <!-- Joint from hand_base to palm_shell -->
          <!-- Joint is "fixed", skipping it -->
          <inertial pos="-0.0175105 -0.0548327 0.00281297" mass="0.0284522" fullinertia="3.01037e-05 3.64689e-05 6.35456e-05 5.0484e-06 -2.1077e-07 2.92246e-06"/>
          <!-- Part palm_shell -->
          <geom type="mesh" class="visual" pos="-0.0200124 -0.0102983 0.0186" quat="0.707107 0.707107 0 0" mesh="palm_shell" material="palm_shell_material"/>
        </body>
      </body>
    </body>
  </worldbody>
  <asset>
    <mesh file="pip_1.stl"/>
    <mesh file="hand_base.stl"/>
    <mesh file="tm_2.stl"/>
    <mesh file="ring_base.stl"/>
    <mesh file="dipt_1.stl"/>
    <mesh file="wrist_mount.stl"/>
    <mesh file="tm_1.stl"/>
    <mesh file="mcp_1.stl"/>
    <mesh file="dip_1.stl"/>
    <mesh file="pipt_2.stl"/>
    <mesh file="pinky_base.stl"/>
    <mesh file="actuator_piston.stl"/>
    <mesh file="fingertip.stl"/>
    <mesh file="clevis_link.stl"/>
    <mesh file="actuator_housing.stl"/>
    <mesh file="index_base.stl"/>
    <mesh file="mcp_2.stl"/>
    <mesh file="clevis_1.stl"/>
    <mesh file="thumb_base.stl"/>
    <mesh file="palm_shell.stl"/>
    <mesh file="pipt_1.stl"/>
    <mesh file="pip_2.stl"/>
    <mesh file="middle_base.stl"/>
    <material name="wrist_mount_material" rgba="0.262745 0.282353 0.301961 1"/>
    <material name="hand_base_material" rgba="0.8 0.74902 0.913725 1"/>
    <material name="index_base_material" rgba="0.654902 0.823529 0.576471 1"/>
    <material name="actuator_housing_material" rgba="0.615686 0.811765 0.929412 1"/>
    <material name="actuator_piston_material" rgba="0.615686 0.811765 0.929412 1"/>
    <material name="mcp_1_material" rgba="0.615686 0.811765 0.929412 1"/>
    <material name="pip_2_material" rgba="0.615686 0.811765 0.929412 1"/>
    <material name="dip_1_material" rgba="0.615686 0.811765 0.929412 1"/>
    <material name="fingertip_material" rgba="0.980392 0.713725 0.00392157 1"/>
    <material name="mcp_2_material" rgba="0.615686 0.811765 0.929412 1"/>
    <material name="pip_1_material" rgba="0.615686 0.811765 0.929412 1"/>
    <material name="middle_base_material" rgba="0.882353 0.572549 0.478431 1"/>
    <material name="ring_base_material" rgba="0.737255 0.937255 0.917647 1"/>
    <material name="pinky_base_material" rgba="0.541176 0.682353 0.839216 1"/>
    <material name="clevis_1_material" rgba="0.615686 0.811765 0.929412 1"/>
    <material name="clevis_link_material" rgba="0.615686 0.811765 0.929412 1"/>
    <material name="thumb_base_material" rgba="0.615686 0.811765 0.929412 1"/>
    <material name="tm_1_material" rgba="0.615686 0.811765 0.929412 1"/>
    <material name="pipt_2_material" rgba="0.615686 0.811765 0.929412 1"/>
    <material name="dipt_1_material" rgba="0.615686 0.811765 0.929412 1"/>
    <material name="tm_2_material" rgba="0.615686 0.811765 0.929412 1"/>
    <material name="pipt_1_material" rgba="0.615686 0.811765 0.929412 1"/>
    <material name="palm_shell_material" rgba="0.980392 0.713725 0.00392157 1"/>
  </asset>
  <actuator>
    <position class="bananaHand" name="indexpiston" joint="indexpiston" inheritrange="1"/>
    <position class="bananaHand" name="middlepiston" joint="middlepiston" inheritrange="1"/>
    <position class="bananaHand" name="ringpiston" joint="ringpiston" inheritrange="1"/>
    <position class="bananaHand" name="pinkypiston" joint="pinkypiston" inheritrange="1"/>
    <position class="bananaHand" name="tmpiston" joint="tmpiston" inheritrange="1"/>
    <position class="bananaHand" name="thumbpiston" joint="thumbpiston" inheritrange="1"/>
  </actuator>
  <equality>
    <connect site1="closing_indexrev3_1" site2="closing_indexrev3_2"/>
    <connect site1="closing_indexrev3_1_z" site2="closing_indexrev3_2_z"/>
    <connect site1="closing_indexrev7_1" site2="closing_indexrev7_2"/>
    <connect site1="closing_indexrev7_1_z" site2="closing_indexrev7_2_z"/>
    <connect site1="closing_indexrev9_1" site2="closing_indexrev9_2"/>
    <connect site1="closing_indexrev9_1_z" site2="closing_indexrev9_2_z"/>
    <connect site1="closing_middlerev3_1" site2="closing_middlerev3_2"/>
    <connect site1="closing_middlerev3_1_z" site2="closing_middlerev3_2_z"/>
    <connect site1="closing_middlerev7_1" site2="closing_middlerev7_2"/>
    <connect site1="closing_middlerev7_1_z" site2="closing_middlerev7_2_z"/>
    <connect site1="closing_middlerev9_1" site2="closing_middlerev9_2"/>
    <connect site1="closing_middlerev9_1_z" site2="closing_middlerev9_2_z"/>
    <connect site1="closing_ringrev3_1" site2="closing_ringrev3_2"/>
    <connect site1="closing_ringrev3_1_z" site2="closing_ringrev3_2_z"/>
    <connect site1="closing_ringrev7_1" site2="closing_ringrev7_2"/>
    <connect site1="closing_ringrev7_1_z" site2="closing_ringrev7_2_z"/>
    <connect site1="closing_ringrev9_1" site2="closing_ringrev9_2"/>
    <connect site1="closing_ringrev9_1_z" site2="closing_ringrev9_2_z"/>
    <connect site1="closing_pinkyrev3_1" site2="closing_pinkyrev3_2"/>
    <connect site1="closing_pinkyrev3_1_z" site2="closing_pinkyrev3_2_z"/>
    <connect site1="closing_pinkyrev7_1" site2="closing_pinkyrev7_2"/>
    <connect site1="closing_pinkyrev7_1_z" site2="closing_pinkyrev7_2_z"/>
    <connect site1="closing_pinkyrev9_1" site2="closing_pinkyrev9_2"/>
    <connect site1="closing_pinkyrev9_1_z" site2="closing_pinkyrev9_2_z"/>
    <connect site1="closing_thumbpivot_1" site2="closing_thumbpivot_2"/>
    <connect site1="closing_thumbpivot_1_z" site2="closing_thumbpivot_2_z"/>
    <connect site1="closing_thumbrev3_1" site2="closing_thumbrev3_2"/>
    <connect site1="closing_thumbrev3_1_z" site2="closing_thumbrev3_2_z"/>
    <connect site1="closing_thumbrev7_1" site2="closing_thumbrev7_2"/>
    <connect site1="closing_thumbrev7_1_z" site2="closing_thumbrev7_2_z"/>
    <connect site1="closing_thumbrev9_1" site2="closing_thumbrev9_2"/>
    <connect site1="closing_thumbrev9_1_z" site2="closing_thumbrev9_2_z"/>
  </equality>
</mujoco>